Workbook

Sheet 00_README
A1: MEM model-ready workbook v2.8 — six physical scenarios finalized | B1: MEM model-ready workbook v2.8 — six physical scenarios finalized | C1: MEM model-ready workbook v2.8 — six physical scenarios finalized | D1: MEM model-ready workbook v2.8 — six physical scenarios finalized | E1: MEM model-ready workbook v2.8 — six physical scenarios finalized | F1: MEM model-ready workbook v2.8 — six physical scenarios finalized | G1: MEM model-ready workbook v2.8 — six physical scenarios finalized | H1: MEM model-ready workbook v2.8 — six physical scenarios finalized | I1: MEM model-ready workbook v2.8 — six physical scenarios finalized | J1: MEM model-ready workbook v2.8 — six physical scenarios finalized
A2: Successor to v2.7. Fixed user-supplied 2025 zonal demand shares, formula-driven Slow/Base/High cases, project-level network delays, and evidence-bounded dispatchable controls. | B2: Successor to v2.7. Fixed user-supplied 2025 zonal demand shares, formula-driven Slow/Base/High cases, project-level network delays, and evidence-bounded dispatchable controls. | C2: Successor to v2.7. Fixed user-supplied 2025 zonal demand shares, formula-driven Slow/Base/High cases, project-level network delays, and evidence-bounded dispatchable controls. | D2: Successor to v2.7. Fixed user-supplied 2025 zonal demand shares, formula-driven Slow/Base/High cases, project-level network delays, and evidence-bounded dispatchable controls. | E2: Successor to v2.7. Fixed user-supplied 2025 zonal demand shares, formula-driven Slow/Base/High cases, project-level network delays, and evidence-bounded dispatchable controls. | F2: Successor to v2.7. Fixed user-supplied 2025 zonal demand shares, formula-driven Slow/Base/High cases, project-level network delays, and evidence-bounded dispatchable controls. | G2: Successor to v2.7. Fixed user-supplied 2025 zonal demand shares, formula-driven Slow/Base/High cases, project-level network delays, and evidence-bounded dispatchable controls. | H2: Successor to v2.7. Fixed user-supplied 2025 zonal demand shares, formula-driven Slow/Base/High cases, project-level network delays, and evidence-bounded dispatchable controls. | I2: Successor to v2.7. Fixed user-supplied 2025 zonal demand shares, formula-driven Slow/Base/High cases, project-level network delays, and evidence-bounded dispatchable controls. | J2: Successor to v2.7. Fixed user-supplied 2025 zonal demand shares, formula-driven Slow/Base/High cases, project-level network delays, and evidence-bounded dispatchable controls.
A4: Item | B4: v2.8 controlling rule | C4: Evidence / boundary
A5: Headline scenarios | B5: Exactly IT2040_SLOW, IT2040_BASE, IT2040_HIGH, IT2050_SLOW, IT2050_BASE, IT2050_HIGH | C5: GA-IT, PNIEC Slow, no-nuclear, CO2, nuclear-availability and weather cases remain secondary overlays.
A6: Base cases | B6: 2040 DE-IT; 2050 PNIEC with 8 GW nuclear | C6: v2.7 analytical baseline retained.
A7: Demand geography | B7: Fixed shares from MEM_2025_ZONAL_DEMAND_FROZEN.csv for total, rigid and P2X | C7: CNORD source label maps to CNOR model zone. No PyPSA-Eur/population reconstruction.
A8: Slow | B8: Base demand; FER and BESS power/energy x0.80; unchanged duration/efficiency; all network projects delayed two years | C8: 2050 Slow network equals recomputed 2040 Slow network.
A9: High | B9: Demand, FER and BESS power/energy x1.10; unchanged duration/efficiency; Base network exactly | C9: No accelerated/new Terna HV project. Distribution flexibility is implicit and outside the HV-zonal model boundary.
A10: Dispatchable 2040 | B10: 55 GW national thermoelectric envelope in all three headline cases | C10: No published CCGT/OCGT or zonal split; plant/cohort geography is a model allocation.
A11: Programmable 2050 | B11: >=30 GW approximate all-programmable adequacy floor in all three headline cases | C11: Not an exact gas total. PNIEC non-nuclear programmable generation is 22.7 TWh; installed technology MW are absent.
A12: Nuclear | B12: 8 GW (5 NORD, 3 CSUD) in every 2050 headline case | C12: Availability variants remain overlays; nuclear is not multiplied with FER.
A13: Network change in Slow | B13: Only 546-P, 563-P and 732-P fall outside 2040 after delay | C13: Every directional delta traces to MEM_v2.8_NETWORK_DELAY_REGISTER.csv.
A14: Reports | B14: No DOCX or PDF edited in this sprint | C14: Final narrative files remain baselines only.
A16: Read 02_SCENARIOS first. Derived scenario values are formulas; external CSV registers provide project/evidence audit trails. | B16: Read 02_SCENARIOS first. Derived scenario values are formulas; external CSV registers provide project/evidence audit trails. | C16: Read 02_SCENARIOS first. Derived scenario values are formulas; external CSV registers provide project/evidence audit trails. | D16: Read 02_SCENARIOS first. Derived scenario values are formulas; external CSV registers provide project/evidence audit trails. | E16: Read 02_SCENARIOS first. Derived scenario values are formulas; external CSV registers provide project/evidence audit trails. | F16: Read 02_SCENARIOS first. Derived scenario values are formulas; external CSV registers provide project/evidence audit trails. | G16: Read 02_SCENARIOS first. Derived scenario values are formulas; external CSV registers provide project/evidence audit trails. | H16: Read 02_SCENARIOS first. Derived scenario values are formulas; external CSV registers provide project/evidence audit trails. | I16: Read 02_SCENARIOS first. Derived scenario values are formulas; external CSV registers provide project/evidence audit trails. | J16: Read 02_SCENARIOS first. Derived scenario values are formulas; external CSV registers provide project/evidence audit trails.

Sheet 01_SOURCES
A1: Registro delle fonti
A2: Fonti ufficiali e benchmark utilizzati nella costruzione degli input. Gli URL sono mantenuti in chiaro.
A4: Source ID | B4: Documento | C4: Autore | D4: Anno | E4: Tipo | F4: Versione/data | G4: Ruolo principale | H4: Scenari | I4: Anni coperti | J4: Geografia | K4: Tecnologie | L4: Contenuto quantitativo | M4: Stato revisione | N4: Uso finale | O4: File / URL | P4: Note
A5: S01 | B5: Stato del sistema elettrico e scenari energetici | C5: Terna S.p.A. | D5: 2025 | E5: Piano di Sviluppo Terna - fascicolo tecnico | F5: Marzo 2025 (PDF modificato 13 marzo 2025) | G5: Baseline storica 2023-2024; struttura del mercato; scenari elettrici 2030-2040; bilanci, capacità e carico residuo. | H5: Storico 2023-2024; PNIEC Policy 2030; PNIEC Slow 2030/2035/2040; DE-IT 2035/2040; richiamo GA-IT/DDS24. | I5: Storico fino al 2024; scenari 2030, 2035, 2040. | J5: Nazionale; zone di mercato; alcune mappe regionali/territoriali; frontiere estere. | K5: Solare, eolico, idroelettrico, bioenergie/altre FER, gas, carbone/olio, accumuli elettrochimici, pompaggi, elettrolizzatori. | L5: Molto elevato: tabelle, mappe, grafici e bilanci. | M5: REVIEWED | N5: CORE | O5: Terna_Piano_Sviluppo_2025_Stato_sistema_elettrico_scenari_energetici_8dd62ec4bbb9f75.pdf | P5: PDF testuale; tabelle parzialmente estraibili; mappe e grafici richiedono verifica visuale/digitalizzazione.
A6: S02 | B6: Piano di Sviluppo 2025 - Overview | C6: Terna S.p.A. | D6: 2025 | E6: Piano di Sviluppo Terna - overview | F6: Marzo 2025 (PDF modificato 13 marzo 2025) | G6: Mappa sintetica del PdS 2025; cross-check di scenari, mercato, investimenti e cronologia rete 2030-2040. | H6: PNIEC/DDS24; orizzonti 2030, 2034 e 2040. | I6: Contesto storico recente; 2030, 2034, 2040. | J6: Nazionale, zonale e interconnessioni estere. | K6: FER, accumuli, generazione termica, data center; infrastrutture AC/HVDC. | L6: Medio-alto: indicatori sintetici, mappe e timeline. | M6: REVIEWED | N6: SUPPORTING | O6: Terna_Piano_Sviluppo_2025_Overview_8dd62ebfc87edf6.pdf | P6: PDF testuale; molti grafici sintetici e mappe da verificare visualmente.
A7: S03 | B7: Benefici di sistema e analisi robustezza rete | C7: Terna S.p.A. | D7: 2025 | E7: Piano di Sviluppo Terna - fascicolo tecnico | F7: Marzo 2025 (PDF modificato 13 marzo 2025) | G7: Capacità di trasporto, effetti con/senza interventi, congestioni, adeguatezza, FER, riserva, emissioni e perdite. | H7: PNIEC 2030; DE-IT 2035/2040; analisi con e senza sviluppi di rete. | I7: 2030, 2035, 2040; confronti con rete di riferimento. | J7: Frontiere estere; zone di mercato italiane; corridoi e aree di rete. | K7: FER, termoelettrico, accumuli; interventi AC/HVDC; risorse inverter-based. | L7: Elevato: capacità, benefici, indicatori di adeguatezza e mappe. | M7: REVIEWED | N7: CORE | O7: Terna_Piano_Sviluppo_2025_Benefici_sistema_analisi_robustezza_rete_8dd62ecc98b2bc9.pdf | P7: PDF testuale; tabelle discrete; mappe/capacità richiedono controllo visuale.
A8: S04 | B8: Programmazione territoriale efficiente e interventi di connessione | C8: Terna S.p.A. | D8: 2025 | E8: Piano di Sviluppo Terna - fascicolo tecnico | F8: Marzo 2025 (PDF modificato 13 marzo 2025) | G8: Pipeline territoriale di connessione; distribuzione regionale/locale; microzone; grandi carichi e opere di connessione. | H8: Richieste 2023-2024; confronto PNIEC Policy 2030; approccio microzonale prospettico. | I8: Storico richieste fino a dicembre 2024; target 2030; progetti in corso. | J8: Nazionale, regionale, provinciale/comunale e microzonale. | K8: Solare, eolico on/offshore, BESS, pompaggi, termoelettrico; data center, RFI, cold ironing, cabine primarie. | L8: Molto elevato: mappe regionali, tabelle pipeline e appendici progetto. | M8: REVIEWED | N8: SUPPORTING | O8: Terna_Piano_Sviluppo_2025_Programmazione_territoriale_efficiente_interventi_connessione_8dd62ec86ec25d1.pdf | P8: PDF testuale ma con numerose mappe/infografiche; appendici tabellari estraibili con revisione.
A9: S05 | B9: Esigenze di sviluppo: i nuovi progetti | C9: Terna S.p.A. | D9: 2025 | E9: Piano di Sviluppo Terna - fascicolo progetti | F9: Marzo 2025 (PDF modificato 13 marzo 2025) | G9: Architettura futura della RTN, capacità interzonali/estere, Hypergrid, cronologia e stato dei progetti. | H9: Target capacity e architetture 2030, 2034, 2040. | I9: 2025-2034; orizzonte architetturale 2040. | J9: Aree Nord-Ovest, Nord-Est, Centro-Sud; zone e frontiere estere; singoli corridoi/progetti. | K9: Linee AC, HVDC/VSC, reconductoring, DTR, stazioni e interconnector. | L9: Elevato: mappe, schede e tabelle di progetto. | M9: REVIEWED | N9: SUPPORTING | O9: Terna_Piano_Sviluppo_2025_Esigenze_sviluppo_nuovi_progetti_8dd62eca67348ba.pdf | P9: PDF testuale; schede progetto e mappe richiedono estrazione strutturata e controllo visuale.
A10: S06 | B10: Pianificazione della rete elettrica | C10: Terna S.p.A. | D10: 2025 | E10: Piano di Sviluppo Terna - fascicolo metodologico | F10: Marzo 2025 (PDF modificato 13 marzo 2025) | G10: Quadro metodologico, normativo e istituzionale; coordinamento TSO-DSO, TYNDP, storage e nuovi carichi. | H10: Pianificazione decennale; TYNDP e cooperazione europea/mediterranea. | I10: 2025-2034; programmi UE 2021-2027; riferimenti prospettici. | J10: Italia, Europa, Mediterraneo; casi nazionali. | K10: Storage, data center, cold ironing, e-mobility; digitalizzazione rete. | L10: Basso-medio: prevalenza descrittiva, alcune figure/tabelle. | M10: REVIEWED | N10: SUPPORTING | O10: Terna_Piano_Sviluppo_2025_Pianificazione_Rete_Elettrica_8dd62ec2378ac53.pdf | P10: PDF testuale; dati numerici limitati.
A11: S07 | B11: Prospettive di Sviluppo del Sistema Energetico 2050 - Copertura della domanda elettrica | C11: Terna S.p.A. | D11: 2025 | E11: Nota tecnica Terna ex Delibera ARERA 392/2024 | F11: 2025 (PDF creato/modificato 27 ottobre 2025) | G11: Fonte primaria 2050: domanda, mix, accumuli, costi tecnologici, adeguatezza e flessibilità. | H11: DDS24 2030-2040; scenari PNIEC 2050 con e senza nucleare; analisi di sensitività. | I11: Storico 2019-2025; 2030, 2040, 2050. | J11: Prevalentemente nazionale; profili temporali nazionali. | K11: Solare, eolico on/offshore, batterie, idroelettrico, gas, nucleare, CCUS/CCS, tecnologie emergenti. | L11: Molto elevato: costi, capacità, bilanci, domanda e flessibilità. | M11: REVIEWED | N11: CORE | O11: Terna Prospettive Sviluppo Sistema Energetico 2050.pdf | P11: PDF testuale; tabelle estraibili; numerosi grafici richiedono verifica/digitalizzazione.
A12: S08 | B12: Piano Nazionale Integrato per l'Energia e il Clima | C12: MASE | D12: 2024 | E12: Piano nazionale energia e clima | F12: Giugno 2024 | G12: Target ufficiali, traiettorie di policy, domanda/consumi settoriali, interconnessioni, prezzi e base analitica. | H12: Scenario di riferimento/WEM; scenario con politiche aggiuntive/PNIEC; proiezioni fino al 2040; ipotesi nucleare 2035-2050. | I12: Storico fino al 2022/2023; obiettivi 2030; proiezioni 2040; alcune ipotesi 2050. | J12: Prevalentemente nazionale; alcuni dati regionali/settoriali; interconnessioni transfrontaliere. | K12: FER elettriche/termiche/trasporti, termoelettrico, nucleare, idrogeno, CCS, reti e accumuli. | L12: Molto elevato ma disperso in 491 pagine. | M12: REVIEWED | N12: CORE | O12: PNIEC 2024.pdf | P12: PDF testuale; molte tabelle estraibili, alcune complesse; figure e note richiedono controllo.
A13: S09 | B13: Documento di Descrizione degli Scenari 2024 | C13: Terna e Snam | D13: 2024 | E13: Documento congiunto di scenario tecnico | F13: 2024 | G13: Fonte primaria 2030-2040 per domanda, capacità FER, bilanci, commodity e risultati di simulazione. | H13: PNIEC Policy; PNIEC Slow; DE-IT; GA-IT | I13: 2023; 2030; 2035; 2040 | J13: Nazionale e sette zone per solare, eolico, accumuli ed elettrolizzatori. | K13: Domanda; FER; storage; H2; termoelettrico aggregato; commodity; bilanci; flussi. | L13: Molto elevato: tabelle e figure direttamente utilizzabili. | M13: REVIEWED | N13: CORE | O13: Documento_Descrizione_Scenari_2024_8dce2430d44d101.pdf | P13: PDF testuale; tabelle estraibili e pagine quantitative verificate visivamente.
A14: S10 | B14: Allegato A.24 al Codice di Rete - Individuazione zone della rete rilevante | C14: Terna | D14: 2021 | E14: Codice di Rete / zonizzazione | F14: Rev. 05 - gennaio 2021 | G14: Definizione ufficiale delle zone NORD e CENTRO SUD | H14: Tutti | I14: Dal 2021 | J14: Italia | K14: Rete / zone di mercato | L14: Composizione regionale delle zone di mercato | M14: REVIEWED | N14: CORE | O14: https://download.terna.it/terna/Allegato%20A.24%20-%20Individuazione%20zone%20della%20rete%20rilevante_8d8bc86c78365d0.pdf | P14: Veneto e Piemonte appartengono alla zona NORD; Lazio alla zona CENTRO SUD.
A15: S11 | B15: Dichiarazione ambientale della Centrale nucleare di Trino | C15: Sogin | D15: 2016 | E15: Dichiarazione ambientale | F15: Aggiornamento 2016 | G15: Ubicazione ufficiale del sito di Trino | H15: 2050 nucleare | I15: Storico / sito | J15: Trino, Piemonte | K15: Nucleare | L15: Coordinate UTM-WGS84 e indirizzo del sito | M15: REVIEWED | N15: CORE | O15: https://www.sogin.it/SiteAssets/uploads/2016/documenti/Dichiarazione_Ambientale_Trino_Aggiornamento_2016.pdf | P15: Coordinate convertite in WGS84: 45.184093 N, 8.277556 E.
A16: S12 | B16: Istruttoria VIA - area Sogin di Borgo Sabotino | C16: Regione Lazio | D16: 2023 | E16: Istruttoria tecnico-amministrativa VIA | F16: 25 agosto 2023 | G16: Ubicazione ufficiale dell'area Sogin di Latina | H16: 2050 nucleare | I16: 2023 | J16: Latina, Lazio | K16: Nucleare / area industriale | L16: Coordinate UTM del centroide dell'area | M16: REVIEWED | N16: CORE | O16: https://regione.lazio.it/sites/default/files/documentazione/AMB-DD-G11375-25-08-2023-Allegato-1.pdf | P16: Coordinate convertite in WGS84: 41.418493 N, 12.809786 E.
... A45: V28-P | B45: MEM v2.8 implementation plan | C45: Stage A checkpoint | D45: 2026 | E45: Markdown | F45: 2026-08-30 | G45: Rules, ranges, QA and limitations | H45: All headline scenarios | I45: 2040/2050 | J45: Workbook-wide | K45: Governance | L45: No material blocker | M45: VERIFIED | N45: CORE | O45: MEM_v2.8_IMPLEMENTATION_PLAN.md | P45: Created before Excel modification.

Sheet 02_SCENARIOS
A1: Controlling scenario matrix — exactly six headline physical scenarios | B1: Controlling scenario matrix — exactly six headline physical scenarios | C1: Controlling scenario matrix — exactly six headline physical scenarios | D1: Controlling scenario matrix — exactly six headline physical scenarios | E1: Controlling scenario matrix — exactly six headline physical scenarios | F1: Controlling scenario matrix — exactly six headline physical scenarios | G1: Controlling scenario matrix — exactly six headline physical scenarios | H1: Controlling scenario matrix — exactly six headline physical scenarios | I1: Controlling scenario matrix — exactly six headline physical scenarios | J1: Controlling scenario matrix — exactly six headline physical scenarios | K1: Controlling scenario matrix — exactly six headline physical scenarios | L1: Controlling scenario matrix — exactly six headline physical scenarios | M1: Controlling scenario matrix — exactly six headline physical scenarios | N1: Controlling scenario matrix — exactly six headline physical scenarios | O1: Controlling scenario matrix — exactly six headline physical scenarios | P1: Controlling scenario matrix — exactly six headline physical scenarios
A2: Scenario multipliers are visible inputs. Slow demand equals Base; High does not accelerate or add RTN projects. | B2: Scenario multipliers are visible inputs. Slow demand equals Base; High does not accelerate or add RTN projects. | C2: Scenario multipliers are visible inputs. Slow demand equals Base; High does not accelerate or add RTN projects. | D2: Scenario multipliers are visible inputs. Slow demand equals Base; High does not accelerate or add RTN projects. | E2: Scenario multipliers are visible inputs. Slow demand equals Base; High does not accelerate or add RTN projects. | F2: Scenario multipliers are visible inputs. Slow demand equals Base; High does not accelerate or add RTN projects. | G2: Scenario multipliers are visible inputs. Slow demand equals Base; High does not accelerate or add RTN projects. | H2: Scenario multipliers are visible inputs. Slow demand equals Base; High does not accelerate or add RTN projects. | I2: Scenario multipliers are visible inputs. Slow demand equals Base; High does not accelerate or add RTN projects. | J2: Scenario multipliers are visible inputs. Slow demand equals Base; High does not accelerate or add RTN projects. | K2: Scenario multipliers are visible inputs. Slow demand equals Base; High does not accelerate or add RTN projects. | L2: Scenario multipliers are visible inputs. Slow demand equals Base; High does not accelerate or add RTN projects. | M2: Scenario multipliers are visible inputs. Slow demand equals Base; High does not accelerate or add RTN projects. | N2: Scenario multipliers are visible inputs. Slow demand equals Base; High does not accelerate or add RTN projects. | O2: Scenario multipliers are visible inputs. Slow demand equals Base; High does not accelerate or add RTN projects. | P2: Scenario multipliers are visible inputs. Slow demand equals Base; High does not accelerate or add RTN projects.
A4: Scenario ID | B4: Horizon | C4: Role | D4: National total TWh | E4: Rigid TWh | F4: P2X TWh | G4: Demand mult. | H4: FER mult. | I4: Storage mult. | J4: Internal network | K4: Foreign network | L4: Dispatchable treatment | M4: Nuclear GW | N4: CO2 default EUR2025/t | O4: Class | P4: Key narrative / model boundary
A5: IT2040_SLOW | B5: 2040 | C5: SLOW | D5: =$B$18 -> 439 | E5: =$B$20 -> 411.5 | F5: =$B$19 -> 27.5 | G5: =$B$16 -> 1 | H5: =$B$15 -> 0.8 | I5: =$B$15 -> 0.8 | J5: +2y project delay; delayed COD <=2040 | K5: Approved 2030 directional floor; project delay register; no added overlay MW | L5: 55 GW national thermal envelope; no backfill | M5: =0 -> 0 | N5: =$B$28 -> 104.55 | O5: Derived scenario | P5: Base demand. FER and BESS power/energy -20%. Slow network removes only delayed project effects crossing 2040.
A6: IT2040_BASE | B6: 2040 | C6: BASE | D6: =$B$18 -> 439 | E6: =$B$20 -> 411.5 | F6: =$B$19 -> 27.5 | G6: =$B$16 -> 1 | H6: =$B$16 -> 1 | I6: =$B$16 -> 1 | J6: Approved PdS 2040 directional values | K6: Approved 2030 directional floor / endogenous PyPSA-Eur | L6: 55 GW national thermal envelope | M6: =0 -> 0 | N6: =$B$28 -> 104.55 | O6: Direct + reconciled | P6: DE-IT 2040 base case.
A7: IT2040_HIGH | B7: 2040 | C7: HIGH | D7: =$B$18*$B$17 -> 482.9 | E7: =$B$20*$B$17 -> 452.65 | F7: =$B$19*$B$17 -> 30.25 | G7: =$B$17 -> 1.1 | H7: =$B$17 -> 1.1 | I7: =$B$17 -> 1.1 | J7: Exactly Base; no acceleration | K7: Exactly Base; no acceleration | L7: 55 GW national thermal envelope; no automatic capacity uplift | M7: =0 -> 0 | N7: =$B$28 -> 104.55 | O7: Derived scenario | P7: 10% higher load is accommodated by 10% more FER/storage plus implicit DSO smart-grid, aggregated demand flexibility and local flexibility outside the explicit HV-zonal boundary.
A8: IT2050_SLOW | B8: 2050 | C8: SLOW | D8: =$B$22 -> 583.1 | E8: =$B$24 -> 501.6 | F8: =$B$23 -> 81.5 | G8: =$B$16 -> 1 | H8: =$B$15 -> 0.8 | I8: =$B$15 -> 0.8 | J8: Exactly recomputed IT2040_SLOW network | K8: Approved 2030 directional floor; same as 2040 Slow | L8: >=30 GW approximate all-programmable adequacy floor; no backfill | M8: =$B$27 -> 8 | N8: =$B$29 -> 400 | O8: Derived scenario | P8: Base demand. FER and BESS power/energy -20%. 8 GW nuclear retained; no-nuclear remains an overlay.
A9: IT2050_BASE | B9: 2050 | C9: BASE | D9: =$B$22 -> 583.1 | E9: =$B$24 -> 501.6 | F9: =$B$23 -> 81.5 | G9: =$B$16 -> 1 | H9: =$B$16 -> 1 | I9: =$B$16 -> 1 | J9: Approved PdS 2040 floor | K9: Approved 2030 directional floor / endogenous PyPSA-Eur | L9: >=30 GW approximate all-programmable adequacy floor | M9: =$B$27 -> 8 | N9: =$B$29 -> 400 | O9: Direct + bridge | P9: PNIEC 2050 with 8 GW nuclear base case.
A10: IT2050_HIGH | B10: 2050 | C10: HIGH | D10: =$B$22*$B$17 -> 641.41 | E10: =$B$24*$B$17 -> 551.76 | F10: =$B$23*$B$17 -> 89.65 | G10: =$B$17 -> 1.1 | H10: =$B$17 -> 1.1 | I10: =$B$17 -> 1.1 | J10: Exactly Base; no acceleration | K10: Exactly Base; no acceleration | L10: >=30 GW approximate all-programmable adequacy floor; no automatic capacity uplift | M10: =$B$27 -> 8 | N10: =$B$29 -> 400 | O10: Derived scenario | P10: 10% higher load is not supported by new/accelerated Terna HV build. Extra accommodation is FER/storage plus implicit distribution and aggregated flexibility outside the explicit model boundary.
A13: Visible scenario parameters | B13: Visible scenario parameters | C13: Visible scenario parameters | E13: Secondary benchmarks and overlays — not headline scenarios | F13: Secondary benchmarks and overlays — not headline scenarios | G13: Secondary benchmarks and overlays — not headline scenarios | H13: Secondary benchmarks and overlays — not headline scenarios | I13: Secondary benchmarks and overlays — not headline scenarios | J13: Secondary benchmarks and overlays — not headline scenarios | K13: Secondary benchmarks and overlays — not headline scenarios | L13: Secondary benchmarks and overlays — not headline scenarios | M13: Secondary benchmarks and overlays — not headline scenarios | N13: Secondary benchmarks and overlays — not headline scenarios | O13: Secondary benchmarks and overlays — not headline scenarios | P13: Secondary benchmarks and overlays — not headline scenarios
A14: Parameter | B14: Value | C14: Use / evidence | E14: Overlay / benchmark | F14: Status | G14: Use
A15: Slow multiplier | B15: 0.8 | C15: FER and BESS power/energy | E15: GA-IT 2040 | F15: Benchmark | G15: Alternative H2/gas/CCS pathway; not High
A16: Base multiplier | B16: 1 | C16: Base and Slow demand | E16: PNIEC Slow 2040 | F16: Benchmark | G16: Evidence reference; not the formula-defined headline Slow
A17: High multiplier | B17: 1.1 | C17: Demand, FER and BESS power/energy | E17: No-nuclear 2050 | F17: Overlay | G17: Counterfactual only
A18: 2040 national total TWh | B18: 439 | C18: DDS DE-IT direct | E18: CO2 175/400/550/1000 | F18: Overlay | G18: Independent market sensitivity
A19: 2040 P2X TWh | B19: 27.5 | C19: DDS direct | E19: Nuclear availability 90.8/92.45/93.4% | F19: Overlay | G19: Independent operating sensitivity
A20: 2040 rigid TWh — reconciled | B20: =B18-B19 -> 411.5 | C20: Total minus P2X; exact arithmetic | E20: Weather / dunkelflaute | F20: Overlay | G20: Independent weather sensitivity
A21: 2040 rigid TWh — legacy rounded | B21: 412 | C21: Reference only; not used in formulas
A22: 2050 national total TWh | B22: 583.1 | C22: PNIEC/Terna direct
A23: 2050 P2X TWh | B23: 81.5 | C23: PNIEC/Terna direct
A24: 2050 rigid TWh | B24: =B22-B23 -> 501.6 | C24: Total minus P2X
A25: 2040 thermal envelope GW | B25: 55 | C25: DDS direct approximate
A26: 2050 programmable floor GW | B26: 30 | C26: Terna derived approximate minimum
A27: 2050 nuclear GW | B27: 8 | C27: PNIEC direct
A28: 2040 CO2 default | B28: 104.55 | C28: Existing v2.7 base
A29: 2050 CO2 default | B29: 400 | C29: Existing v2.7 base

Sheet 03_ZONE_MAP
A1: Crosswalk geografico
A2: Regioni e aree assegnate alle zone di mercato e ai bus canonici PyPSA.
A4: Record ID | B4: Tipo record | C4: Regione/area | D4: Tipo unità | E4: Codice zona | F4: Zona | G4: Bus PyPSA | H4: Validità | I4: Status | J4: Affidabilità | K4: Regola assegnazione | L4: Fonte | M4: URL fonte | N4: Note
A5: GEO-001 | B5: Region-to-market-zone | C5: Valle d'Aosta | D5: Region | E5: NORD | F5: Nord | G5: IT_NORD | H5: 2021-01-01 | I5: Current official association | J5: A — Official Terna A.24 | K5: Direct region association; plant/load coordinates and official zone code override any coarse aggregation | L5: A24 | M5: https://download.terna.it/terna/Allegato%20A.24%20-%20Individuazione%20zone%20della%20rete%20rilevante_8d8bc86c78365d0.pdf | N5: Spot-market geographic zone; not Capacity Market sub-area.
A6: GEO-002 | B6: Region-to-market-zone | C6: Piemonte | D6: Region | E6: NORD | F6: Nord | G6: IT_NORD | H6: 2021-01-01 | I6: Current official association | J6: A — Official Terna A.24 | K6: Direct region association; plant/load coordinates and official zone code override any coarse aggregation | L6: A24 | M6: https://download.terna.it/terna/Allegato%20A.24%20-%20Individuazione%20zone%20della%20rete%20rilevante_8d8bc86c78365d0.pdf | N6: Spot-market geographic zone; not Capacity Market sub-area.
A7: GEO-003 | B7: Region-to-market-zone | C7: Liguria | D7: Region | E7: NORD | F7: Nord | G7: IT_NORD | H7: 2021-01-01 | I7: Current official association | J7: A — Official Terna A.24 | K7: Direct region association; plant/load coordinates and official zone code override any coarse aggregation | L7: A24 | M7: https://download.terna.it/terna/Allegato%20A.24%20-%20Individuazione%20zone%20della%20rete%20rilevante_8d8bc86c78365d0.pdf | N7: Spot-market geographic zone; not Capacity Market sub-area.
A8: GEO-004 | B8: Region-to-market-zone | C8: Lombardia | D8: Region | E8: NORD | F8: Nord | G8: IT_NORD | H8: 2021-01-01 | I8: Current official association | J8: A — Official Terna A.24 | K8: Direct region association; plant/load coordinates and official zone code override any coarse aggregation | L8: A24 | M8: https://download.terna.it/terna/Allegato%20A.24%20-%20Individuazione%20zone%20della%20rete%20rilevante_8d8bc86c78365d0.pdf | N8: Spot-market geographic zone; not Capacity Market sub-area.
A9: GEO-005 | B9: Region-to-market-zone | C9: Trentino-Alto Adige | D9: Region | E9: NORD | F9: Nord | G9: IT_NORD | H9: 2021-01-01 | I9: Current official association | J9: A — Official Terna A.24 | K9: Direct region association; plant/load coordinates and official zone code override any coarse aggregation | L9: A24 | M9: https://download.terna.it/terna/Allegato%20A.24%20-%20Individuazione%20zone%20della%20rete%20rilevante_8d8bc86c78365d0.pdf | N9: Spot-market geographic zone; not Capacity Market sub-area.
A10: GEO-006 | B10: Region-to-market-zone | C10: Veneto | D10: Region | E10: NORD | F10: Nord | G10: IT_NORD | H10: 2021-01-01 | I10: Current official association | J10: A — Official Terna A.24 | K10: Direct region association; plant/load coordinates and official zone code override any coarse aggregation | L10: A24 | M10: https://download.terna.it/terna/Allegato%20A.24%20-%20Individuazione%20zone%20della%20rete%20rilevante_8d8bc86c78365d0.pdf | N10: Spot-market geographic zone; not Capacity Market sub-area.
A11: GEO-007 | B11: Region-to-market-zone | C11: Friuli-Venezia Giulia | D11: Region | E11: NORD | F11: Nord | G11: IT_NORD | H11: 2021-01-01 | I11: Current official association | J11: A — Official Terna A.24 | K11: Direct region association; plant/load coordinates and official zone code override any coarse aggregation | L11: A24 | M11: https://download.terna.it/terna/Allegato%20A.24%20-%20Individuazione%20zone%20della%20rete%20rilevante_8d8bc86c78365d0.pdf | N11: Spot-market geographic zone; not Capacity Market sub-area.
A12: GEO-008 | B12: Region-to-market-zone | C12: Emilia-Romagna | D12: Region | E12: NORD | F12: Nord | G12: IT_NORD | H12: 2021-01-01 | I12: Current official association | J12: A — Official Terna A.24 | K12: Direct region association; plant/load coordinates and official zone code override any coarse aggregation | L12: A24 | M12: https://download.terna.it/terna/Allegato%20A.24%20-%20Individuazione%20zone%20della%20rete%20rilevante_8d8bc86c78365d0.pdf | N12: Spot-market geographic zone; not Capacity Market sub-area.
A13: GEO-009 | B13: Region-to-market-zone | C13: Toscana | D13: Region | E13: CNOR | F13: Centro Nord | G13: IT_CNOR | H13: 2021-01-01 | I13: Current official association | J13: A — Official Terna A.24 | K13: Direct region association; plant/load coordinates and official zone code override any coarse aggregation | L13: A24 | M13: https://download.terna.it/terna/Allegato%20A.24%20-%20Individuazione%20zone%20della%20rete%20rilevante_8d8bc86c78365d0.pdf | N13: Spot-market geographic zone; not Capacity Market sub-area.
A14: GEO-010 | B14: Region-to-market-zone | C14: Marche | D14: Region | E14: CNOR | F14: Centro Nord | G14: IT_CNOR | H14: 2021-01-01 | I14: Current official association | J14: A — Official Terna A.24 | K14: Direct region association; plant/load coordinates and official zone code override any coarse aggregation | L14: A24 | M14: https://download.terna.it/terna/Allegato%20A.24%20-%20Individuazione%20zone%20della%20rete%20rilevante_8d8bc86c78365d0.pdf | N14: Spot-market geographic zone; not Capacity Market sub-area.
A15: GEO-011 | B15: Region-to-market-zone | C15: Umbria | D15: Region | E15: CSUD | F15: Centro Sud | G15: IT_CSUD | H15: 2021-01-01 | I15: Current official association | J15: A — Official Terna A.24 | K15: Direct region association; plant/load coordinates and official zone code override any coarse aggregation | L15: A24 | M15: https://download.terna.it/terna/Allegato%20A.24%20-%20Individuazione%20zone%20della%20rete%20rilevante_8d8bc86c78365d0.pdf | N15: Spot-market geographic zone; not Capacity Market sub-area.
... A34: GEO-030 | B34: Foreign bidding area | C34: Tunisia | D34: Country / virtual zone | E34: TN | F34: Tunisia — future | G34: TN | H34: Current / project-specific | I34: External/virtual modelling node | J34: A/B | K34: Use endogenous PyPSA-Eur bus where represented; otherwise collapsed external bus with explicit price/import assumption | L34: S01 / S09 | M34: https://download.terna.it/terna/Terna_Piano_Sviluppo_2025_Stato_sistema_elettrico_scenari_energetici_8dd62ec4bbb9f75.pdf | N34: Not an Italian geographic bidding zone.

Sheet 04_GENERATION_BY_ZONE
A1: Generation capacity by zone — Slow / Base / High | B1: Generation capacity by zone — Slow / Base / High | C1: Generation capacity by zone — Slow / Base / High | D1: Generation capacity by zone — Slow / Base / High | E1: Generation capacity by zone — Slow / Base / High | F1: Generation capacity by zone — Slow / Base / High | G1: Generation capacity by zone — Slow / Base / High | H1: Generation capacity by zone — Slow / Base / High | I1: Generation capacity by zone — Slow / Base / High | J1: Generation capacity by zone — Slow / Base / High | K1: Generation capacity by zone — Slow / Base / High
A2: FER is formula-driven at 0.80 / 1.00 / 1.10. Nuclear remains 0 GW in 2040 and 8 GW in all 2050 headline cases. Dispatchable national controls are separated from absent zonal allocations. | B2: FER is formula-driven at 0.80 / 1.00 / 1.10. Nuclear remains 0 GW in 2040 and 8 GW in all 2050 headline cases. Dispatchable national controls are separated from absent zonal allocations. | C2: FER is formula-driven at 0.80 / 1.00 / 1.10. Nuclear remains 0 GW in 2040 and 8 GW in all 2050 headline cases. Dispatchable national controls are separated from absent zonal allocations. | D2: FER is formula-driven at 0.80 / 1.00 / 1.10. Nuclear remains 0 GW in 2040 and 8 GW in all 2050 headline cases. Dispatchable national controls are separated from absent zonal allocations. | E2: FER is formula-driven at 0.80 / 1.00 / 1.10. Nuclear remains 0 GW in 2040 and 8 GW in all 2050 headline cases. Dispatchable national controls are separated from absent zonal allocations. | F2: FER is formula-driven at 0.80 / 1.00 / 1.10. Nuclear remains 0 GW in 2040 and 8 GW in all 2050 headline cases. Dispatchable national controls are separated from absent zonal allocations. | G2: FER is formula-driven at 0.80 / 1.00 / 1.10. Nuclear remains 0 GW in 2040 and 8 GW in all 2050 headline cases. Dispatchable national controls are separated from absent zonal allocations. | H2: FER is formula-driven at 0.80 / 1.00 / 1.10. Nuclear remains 0 GW in 2040 and 8 GW in all 2050 headline cases. Dispatchable national controls are separated from absent zonal allocations. | I2: FER is formula-driven at 0.80 / 1.00 / 1.10. Nuclear remains 0 GW in 2040 and 8 GW in all 2050 headline cases. Dispatchable national controls are separated from absent zonal allocations. | J2: FER is formula-driven at 0.80 / 1.00 / 1.10. Nuclear remains 0 GW in 2040 and 8 GW in all 2050 headline cases. Dispatchable national controls are separated from absent zonal allocations. | K2: FER is formula-driven at 0.80 / 1.00 / 1.10. Nuclear remains 0 GW in 2040 and 8 GW in all 2050 headline cases. Dispatchable national controls are separated from absent zonal allocations.
A4: Zone | B4: Technology | C4: 2040 Slow GW | D4: 2040 Base GW | E4: 2040 High GW | F4: 2050 Slow GW | G4: 2050 Base GW | H4: 2050 High GW | I4: Evidence | J4: Class | K4: Zonal allocation flag
A5: NORD | B5: Solar rooftop / distributed | C5: =D5*'02_SCENARIOS'!$H$5 -> 20.08 | D5: 25.1 | E5: =D5*'02_SCENARIOS'!$H$7 -> 27.61 | F5: =G5*'02_SCENARIOS'!$H$8 -> 40.691481 | G5: 50.864351 | H5: =G5*'02_SCENARIOS'!$H$10 -> 55.950786 | I5: v2.7 Base; DDS/PNIEC national controls | J5: Direct national / inherited zonal proxy | K5: USER DECISION: v2.7 zonal allocation retained
A6: NORD | B6: Solar utility | C6: =D6*'02_SCENARIOS'!$H$5 -> 13.84 | D6: 17.3 | E6: =D6*'02_SCENARIOS'!$H$7 -> 19.03 | F6: =G6*'02_SCENARIOS'!$H$8 -> 28.046319 | G6: 35.057899 | H6: =G6*'02_SCENARIOS'!$H$10 -> 38.563689 | I6: v2.7 Base; DDS/PNIEC national controls | J6: Direct national / inherited zonal proxy | K6: USER DECISION: v2.7 zonal allocation retained
A7: NORD | B7: Wind onshore | C7: =D7*'02_SCENARIOS'!$H$5 -> 0.48 | D7: 0.6 | E7: =D7*'02_SCENARIOS'!$H$7 -> 0.66 | F7: =G7*'02_SCENARIOS'!$H$8 -> 0.50674487 | G7: 0.63343109 | H7: =G7*'02_SCENARIOS'!$H$10 -> 0.69677419 | I7: v2.7 Base; DDS/PNIEC national controls | J7: Direct national / inherited zonal proxy | K7: USER DECISION: v2.7 zonal allocation retained
A8: NORD | B8: Wind offshore | C8: =D8*'02_SCENARIOS'!$H$5 -> 1.2 | D8: 1.5 | E8: =D8*'02_SCENARIOS'!$H$7 -> 1.65 | F8: =G8*'02_SCENARIOS'!$H$8 -> 1.1842105 | G8: 1.4802632 | H8: =G8*'02_SCENARIOS'!$H$10 -> 1.6282895 | I8: v2.7 Base; DDS/PNIEC national controls | J8: Direct national / inherited zonal proxy | K8: USER DECISION: v2.7 zonal allocation retained
A9: NORD | B9: Nuclear | C9: =D9 -> 0 | D9: 0 | E9: =D9 -> 0 | F9: =G9 -> 5 | G9: 5 | H9: =G9 -> 5 | I9: PNIEC 8 GW; approved 5 NORD / 3 CSUD | J9: Direct national + approved project allocation | K9: APPROVED
A10: CNOR | B10: Solar rooftop / distributed | C10: =D10*'02_SCENARIOS'!$H$5 -> 2.64 | D10: 3.3 | E10: =D10*'02_SCENARIOS'!$H$7 -> 3.63 | F10: =G10*'02_SCENARIOS'!$H$8 -> 5.3498759 | G10: 6.6873449 | H10: =G10*'02_SCENARIOS'!$H$10 -> 7.3560794 | I10: v2.7 Base; DDS/PNIEC national controls | J10: Direct national / inherited zonal proxy | K10: USER DECISION: v2.7 zonal allocation retained
A11: CNOR | B11: Solar utility | C11: =D11*'02_SCENARIOS'!$H$5 -> 5.04 | D11: 6.3 | E11: =D11*'02_SCENARIOS'!$H$7 -> 6.93 | F11: =G11*'02_SCENARIOS'!$H$8 -> 10.2134 | G11: 12.766749 | H11: =G11*'02_SCENARIOS'!$H$10 -> 14.043424 | I11: v2.7 Base; DDS/PNIEC national controls | J11: Direct national / inherited zonal proxy | K11: USER DECISION: v2.7 zonal allocation retained
A12: CNOR | B12: Wind onshore | C12: =D12*'02_SCENARIOS'!$H$5 -> 0.32 | D12: 0.4 | E12: =D12*'02_SCENARIOS'!$H$7 -> 0.44 | F12: =G12*'02_SCENARIOS'!$H$8 -> 0.33782991 | G12: 0.42228739 | H12: =G12*'02_SCENARIOS'!$H$10 -> 0.46451613 | I12: v2.7 Base; DDS/PNIEC national controls | J12: Direct national / inherited zonal proxy | K12: USER DECISION: v2.7 zonal allocation retained
A13: CNOR | B13: Wind offshore | C13: =D13*'02_SCENARIOS'!$H$5 -> 0.64 | D13: 0.8 | E13: =D13*'02_SCENARIOS'!$H$7 -> 0.88 | F13: =G13*'02_SCENARIOS'!$H$8 -> 0.63157895 | G13: 0.78947368 | H13: =G13*'02_SCENARIOS'!$H$10 -> 0.86842105 | I13: v2.7 Base; DDS/PNIEC national controls | J13: Direct national / inherited zonal proxy | K13: USER DECISION: v2.7 zonal allocation retained
A14: CNOR | B14: Nuclear | C14: =D14 -> 0 | D14: 0 | E14: =D14 -> 0 | F14: =G14 -> 0 | G14: 0 | H14: =G14 -> 0 | I14: PNIEC 8 GW; approved 5 NORD / 3 CSUD | J14: Direct national + approved project allocation | K14: APPROVED
A15: CSUD | B15: Solar rooftop / distributed | C15: =D15*'02_SCENARIOS'!$H$5 -> 4.4 | D15: 5.5 | E15: =D15*'02_SCENARIOS'!$H$7 -> 6.05 | F15: =G15*'02_SCENARIOS'!$H$8 -> 8.9164599 | G15: 11.145575 | H15: =G15*'02_SCENARIOS'!$H$10 -> 12.260132 | I15: v2.7 Base; DDS/PNIEC national controls | J15: Direct national / inherited zonal proxy | K15: USER DECISION: v2.7 zonal allocation retained
A16: CSUD | B16: Solar utility | C16: =D16*'02_SCENARIOS'!$H$5 -> 11.68 | D16: 14.6 | E16: =D16*'02_SCENARIOS'!$H$7 -> 16.06 | F16: =G16*'02_SCENARIOS'!$H$8 -> 23.669148 | G16: 29.586435 | H16: =G16*'02_SCENARIOS'!$H$10 -> 32.545079 | I16: v2.7 Base; DDS/PNIEC national controls | J16: Direct national / inherited zonal proxy | K16: USER DECISION: v2.7 zonal allocation retained
A17: CSUD | B17: Wind onshore | C17: =D17*'02_SCENARIOS'!$H$5 -> 5.44 | D17: 6.8 | E17: =D17*'02_SCENARIOS'!$H$7 -> 7.48 | F17: =G17*'02_SCENARIOS'!$H$8 -> 5.7431085 | G17: 7.1788856 | H17: =G17*'02_SCENARIOS'!$H$10 -> 7.8967742 | I17: v2.7 Base; DDS/PNIEC national controls | J17: Direct national / inherited zonal proxy | K17: USER DECISION: v2.7 zonal allocation retained
A18: CSUD | B18: Wind offshore | C18: =D18*'02_SCENARIOS'!$H$5 -> 1.28 | D18: 1.6 | E18: =D18*'02_SCENARIOS'!$H$7 -> 1.76 | F18: =G18*'02_SCENARIOS'!$H$8 -> 1.2631579 | G18: 1.5789474 | H18: =G18*'02_SCENARIOS'!$H$10 -> 1.7368421 | I18: v2.7 Base; DDS/PNIEC national controls | J18: Direct national / inherited zonal proxy | K18: USER DECISION: v2.7 zonal allocation retained
A19: CSUD | B19: Nuclear | C19: =D19 -> 0 | D19: 0 | E19: =D19 -> 0 | F19: =G19 -> 3 | G19: 3 | H19: =G19 -> 3 | I19: PNIEC 8 GW; approved 5 NORD / 3 CSUD | J19: Direct national + approved project allocation | K19: APPROVED
A20: SUD | B20: Solar rooftop / distributed | C20: =D20*'02_SCENARIOS'!$H$5 -> 1.36 | D20: 1.7 | E20: =D20*'02_SCENARIOS'!$H$7 -> 1.87 | F20: =G20*'02_SCENARIOS'!$H$8 -> 2.7559967 | G20: 3.4449959 | H20: =G20*'02_SCENARIOS'!$H$10 -> 3.7894955 | I20: v2.7 Base; DDS/PNIEC national controls | J20: Direct national / inherited zonal proxy | K20: USER DECISION: v2.7 zonal allocation retained
A21: SUD | B21: Solar utility | C21: =D21*'02_SCENARIOS'!$H$5 -> 15.44 | D21: 19.3 | E21: =D21*'02_SCENARIOS'!$H$7 -> 21.23 | F21: =G21*'02_SCENARIOS'!$H$8 -> 31.288668 | G21: 39.110835 | H21: =G21*'02_SCENARIOS'!$H$10 -> 43.021919 | I21: v2.7 Base; DDS/PNIEC national controls | J21: Direct national / inherited zonal proxy | K21: USER DECISION: v2.7 zonal allocation retained
A22: SUD | B22: Wind onshore | C22: =D22*'02_SCENARIOS'!$H$5 -> 10.56 | D22: 13.2 | E22: =D22*'02_SCENARIOS'!$H$7 -> 14.52 | F22: =G22*'02_SCENARIOS'!$H$8 -> 11.148387 | G22: 13.935484 | H22: =G22*'02_SCENARIOS'!$H$10 -> 15.329032 | I22: v2.7 Base; DDS/PNIEC national controls | J22: Direct national / inherited zonal proxy | K22: USER DECISION: v2.7 zonal allocation retained
A23: SUD | B23: Wind offshore | C23: =D23*'02_SCENARIOS'!$H$5 -> 3.76 | D23: 4.7 | E23: =D23*'02_SCENARIOS'!$H$7 -> 5.17 | F23: =G23*'02_SCENARIOS'!$H$8 -> 3.7105263 | G23: 4.6381579 | H23: =G23*'02_SCENARIOS'!$H$10 -> 5.1019737 | I23: v2.7 Base; DDS/PNIEC national controls | J23: Direct national / inherited zonal proxy | K23: USER DECISION: v2.7 zonal allocation retained
A24: SUD | B24: Nuclear | C24: =D24 -> 0 | D24: 0 | E24: =D24 -> 0 | F24: =G24 -> 0 | G24: 0 | H24: =G24 -> 0 | I24: PNIEC 8 GW; approved 5 NORD / 3 CSUD | J24: Direct national + approved project allocation | K24: APPROVED
A25: CALA | B25: Solar rooftop / distributed | C25: =D25*'02_SCENARIOS'!$H$5 -> 0.88 | D25: 1.1 | E25: =D25*'02_SCENARIOS'!$H$7 -> 1.21 | F25: =G25*'02_SCENARIOS'!$H$8 -> 1.783292 | G25: 2.229115 | H25: =G25*'02_SCENARIOS'!$H$10 -> 2.4520265 | I25: v2.7 Base; DDS/PNIEC national controls | J25: Direct national / inherited zonal proxy | K25: USER DECISION: v2.7 zonal allocation retained
A26: CALA | B26: Solar utility | C26: =D26*'02_SCENARIOS'!$H$5 -> 2 | D26: 2.5 | E26: =D26*'02_SCENARIOS'!$H$7 -> 2.75 | F26: =G26*'02_SCENARIOS'!$H$8 -> 4.0529363 | G26: 5.0661704 | H26: =G26*'02_SCENARIOS'!$H$10 -> 5.5727874 | I26: v2.7 Base; DDS/PNIEC national controls | J26: Direct national / inherited zonal proxy | K26: USER DECISION: v2.7 zonal allocation retained
A27: CALA | B27: Wind onshore | C27: =D27*'02_SCENARIOS'!$H$5 -> 2.64 | D27: 3.3 | E27: =D27*'02_SCENARIOS'!$H$7 -> 3.63 | F27: =G27*'02_SCENARIOS'!$H$8 -> 2.7870968 | G27: 3.483871 | H27: =G27*'02_SCENARIOS'!$H$10 -> 3.8322581 | I27: v2.7 Base; DDS/PNIEC national controls | J27: Direct national / inherited zonal proxy | K27: USER DECISION: v2.7 zonal allocation retained
A28: CALA | B28: Wind offshore | C28: =D28*'02_SCENARIOS'!$H$5 -> 0.48 | D28: 0.6 | E28: =D28*'02_SCENARIOS'!$H$7 -> 0.66 | F28: =G28*'02_SCENARIOS'!$H$8 -> 0.47368421 | G28: 0.59210526 | H28: =G28*'02_SCENARIOS'!$H$10 -> 0.65131579 | I28: v2.7 Base; DDS/PNIEC national controls | J28: Direct national / inherited zonal proxy | K28: USER DECISION: v2.7 zonal allocation retained
A29: CALA | B29: Nuclear | C29: =D29 -> 0 | D29: 0 | E29: =D29 -> 0 | F29: =G29 -> 0 | G29: 0 | H29: =G29 -> 0 | I29: PNIEC 8 GW; approved 5 NORD / 3 CSUD | J29: Direct national + approved project allocation | K29: APPROVED
A30: SICI | B30: Solar rooftop / distributed | C30: =D30*'02_SCENARIOS'!$H$5 -> 2.64 | D30: 3.3 | E30: =D30*'02_SCENARIOS'!$H$7 -> 3.63 | F30: =G30*'02_SCENARIOS'!$H$8 -> 5.3498759 | G30: 6.6873449 | H30: =G30*'02_SCENARIOS'!$H$10 -> 7.3560794 | I30: v2.7 Base; DDS/PNIEC national controls | J30: Direct national / inherited zonal proxy | K30: USER DECISION: v2.7 zonal allocation retained
A31: SICI | B31: Solar utility | C31: =D31*'02_SCENARIOS'!$H$5 -> 9.2 | D31: 11.5 | E31: =D31*'02_SCENARIOS'!$H$7 -> 12.65 | F31: =G31*'02_SCENARIOS'!$H$8 -> 18.643507 | G31: 23.304384 | H31: =G31*'02_SCENARIOS'!$H$10 -> 25.634822 | I31: v2.7 Base; DDS/PNIEC national controls | J31: Direct national / inherited zonal proxy | K31: USER DECISION: v2.7 zonal allocation retained
A32: SICI | B32: Wind onshore | C32: =D32*'02_SCENARIOS'!$H$5 -> 5.04 | D32: 6.3 | E32: =D32*'02_SCENARIOS'!$H$7 -> 6.93 | F32: =G32*'02_SCENARIOS'!$H$8 -> 5.3208211 | G32: 6.6510264 | H32: =G32*'02_SCENARIOS'!$H$10 -> 7.316129 | I32: v2.7 Base; DDS/PNIEC national controls | J32: Direct national / inherited zonal proxy | K32: USER DECISION: v2.7 zonal allocation retained
A33: SICI | B33: Wind offshore | C33: =D33*'02_SCENARIOS'!$H$5 -> 2.4 | D33: 3 | E33: =D33*'02_SCENARIOS'!$H$7 -> 3.3 | F33: =G33*'02_SCENARIOS'!$H$8 -> 2.3684211 | G33: 2.9605263 | H33: =G33*'02_SCENARIOS'!$H$10 -> 3.2565789 | I33: v2.7 Base; DDS/PNIEC national controls | J33: Direct national / inherited zonal proxy | K33: USER DECISION: v2.7 zonal allocation retained
A34: SICI | B34: Nuclear | C34: =D34 -> 0 | D34: 0 | E34: =D34 -> 0 | F34: =G34 -> 0 | G34: 0 | H34: =G34 -> 0 | I34: PNIEC 8 GW; approved 5 NORD / 3 CSUD | J34: Direct national + approved project allocation | K34: APPROVED
A35: SARD | B35: Solar rooftop / distributed | C35: =D35*'02_SCENARIOS'!$H$5 -> 1.36 | D35: 1.7 | E35: =D35*'02_SCENARIOS'!$H$7 -> 1.87 | F35: =G35*'02_SCENARIOS'!$H$8 -> 2.7559967 | G35: 3.4449959 | H35: =G35*'02_SCENARIOS'!$H$10 -> 3.7894955 | I35: v2.7 Base; DDS/PNIEC national controls | J35: Direct national / inherited zonal proxy | K35: USER DECISION: v2.7 zonal allocation retained
A36: SARD | B36: Solar utility | C36: =D36*'02_SCENARIOS'!$H$5 -> 6.16 | D36: 7.7 | E36: =D36*'02_SCENARIOS'!$H$7 -> 8.47 | F36: =G36*'02_SCENARIOS'!$H$8 -> 12.483044 | G36: 15.603805 | H36: =G36*'02_SCENARIOS'!$H$10 -> 17.164185 | I36: v2.7 Base; DDS/PNIEC national controls | J36: Direct national / inherited zonal proxy | K36: USER DECISION: v2.7 zonal allocation retained
A37: SARD | B37: Wind onshore | C37: =D37*'02_SCENARIOS'!$H$5 -> 2.8 | D37: 3.5 | E37: =D37*'02_SCENARIOS'!$H$7 -> 3.85 | F37: =G37*'02_SCENARIOS'!$H$8 -> 2.9560117 | G37: 3.6950147 | H37: =G37*'02_SCENARIOS'!$H$10 -> 4.0645161 | I37: v2.7 Base; DDS/PNIEC national controls | J37: Direct national / inherited zonal proxy | K37: USER DECISION: v2.7 zonal allocation retained
A38: SARD | B38: Wind offshore | C38: =D38*'02_SCENARIOS'!$H$5 -> 2.4 | D38: 3 | E38: =D38*'02_SCENARIOS'!$H$7 -> 3.3 | F38: =G38*'02_SCENARIOS'!$H$8 -> 2.3684211 | G38: 2.9605263 | H38: =G38*'02_SCENARIOS'!$H$10 -> 3.2565789 | I38: v2.7 Base; DDS/PNIEC national controls | J38: Direct national / inherited zonal proxy | K38: USER DECISION: v2.7 zonal allocation retained
A39: SARD | B39: Nuclear | C39: =D39 -> 0 | D39: 0 | E39: =D39 -> 0 | F39: =G39 -> 0 | G39: 0 | H39: =G39 -> 0 | I39: PNIEC 8 GW; approved 5 NORD / 3 CSUD | J39: Direct national + approved project allocation | K39: APPROVED
A41: NATIONAL | B41: FRNP listed total | C41: =SUM(C5,C6,C7,C8,C10,C11,C12,C13,C15,C16,C17,C18,C20,C21,C22,C23,C25,C26,C27,C28,C30,C31,C32,C33,C35,C36,C37,C38) -> 136.16 | D41: =SUM(D5,D6,D7,D8,D10,D11,D12,D13,D15,D16,D17,D18,D20,D21,D22,D23,D25,D26,D27,D28,D30,D31,D32,D33,D35,D36,D37,D38) -> 170.2 | E41: =SUM(E5,E6,E7,E8,E10,E11,E12,E13,E15,E16,E17,E18,E20,E21,E22,E23,E25,E26,E27,E28,E30,E31,E32,E33,E35,E36,E37,E38) -> 187.22 | F41: =SUM(F5,F6,F7,F8,F10,F11,F12,F13,F15,F16,F17,F18,F20,F21,F22,F23,F25,F26,F27,F28,F30,F31,F32,F33,F35,F36,F37,F38) -> 236.8 | G41: =SUM(G5,G6,G7,G8,G10,G11,G12,G13,G15,G16,G17,G18,G20,G21,G22,G23,G25,G26,G27,G28,G30,G31,G32,G33,G35,G36,G37,G38) -> 296 | H41: =SUM(H5,H6,H7,H8,H10,H11,H12,H13,H15,H16,H17,H18,H20,H21,H22,H23,H25,H26,H27,H28,H30,H31,H32,H33,H35,H36,H37,H38) -> 325.6 | I41: Solar + onshore + offshore | J41: Formula | K41: QA
A42: NATIONAL | B42: Nuclear total | C42: =SUM(C9,C14,C19,C24,C29,C34,C39) -> 0 | D42: =SUM(D9,D14,D19,D24,D29,D34,D39) -> 0 | E42: =SUM(E9,E14,E19,E24,E29,E34,E39) -> 0 | F42: =SUM(F9,F14,F19,F24,F29,F34,F39) -> 8 | G42: =SUM(G9,G14,G19,G24,G29,G34,G39) -> 8 | H42: =SUM(H9,H14,H19,H24,H29,H34,H39) -> 8 | I42: 8 GW 2050 | J42: Formula | K42: QA
...

Sheet 05_STORAGE_BY_ZONE
A1: Battery storage by zone — power, energy, duration and efficiency | B1: Battery storage by zone — power, energy, duration and efficiency | C1: Battery storage by zone — power, energy, duration and efficiency | D1: Battery storage by zone — power, energy, duration and efficiency | E1: Battery storage by zone — power, energy, duration and efficiency | F1: Battery storage by zone — power, energy, duration and efficiency | G1: Battery storage by zone — power, energy, duration and efficiency | H1: Battery storage by zone — power, energy, duration and efficiency | I1: Battery storage by zone — power, energy, duration and efficiency | J1: Battery storage by zone — power, energy, duration and efficiency | K1: Battery storage by zone — power, energy, duration and efficiency | L1: Battery storage by zone — power, energy, duration and efficiency | M1: Battery storage by zone — power, energy, duration and efficiency | N1: Battery storage by zone — power, energy, duration and efficiency | O1: Battery storage by zone — power, energy, duration and efficiency | P1: Battery storage by zone — power, energy, duration and efficiency
A2: Slow and High multiply both charging power, discharging power and energy by 0.80 / 1.10. Duration and one-way/round-trip efficiencies remain unchanged. MACSE is a subset and is not summed twice. | B2: Slow and High multiply both charging power, discharging power and energy by 0.80 / 1.10. Duration and one-way/round-trip efficiencies remain unchanged. MACSE is a subset and is not summed twice. | C2: Slow and High multiply both charging power, discharging power and energy by 0.80 / 1.10. Duration and one-way/round-trip efficiencies remain unchanged. MACSE is a subset and is not summed twice. | D2: Slow and High multiply both charging power, discharging power and energy by 0.80 / 1.10. Duration and one-way/round-trip efficiencies remain unchanged. MACSE is a subset and is not summed twice. | E2: Slow and High multiply both charging power, discharging power and energy by 0.80 / 1.10. Duration and one-way/round-trip efficiencies remain unchanged. MACSE is a subset and is not summed twice. | F2: Slow and High multiply both charging power, discharging power and energy by 0.80 / 1.10. Duration and one-way/round-trip efficiencies remain unchanged. MACSE is a subset and is not summed twice. | G2: Slow and High multiply both charging power, discharging power and energy by 0.80 / 1.10. Duration and one-way/round-trip efficiencies remain unchanged. MACSE is a subset and is not summed twice. | H2: Slow and High multiply both charging power, discharging power and energy by 0.80 / 1.10. Duration and one-way/round-trip efficiencies remain unchanged. MACSE is a subset and is not summed twice. | I2: Slow and High multiply both charging power, discharging power and energy by 0.80 / 1.10. Duration and one-way/round-trip efficiencies remain unchanged. MACSE is a subset and is not summed twice. | J2: Slow and High multiply both charging power, discharging power and energy by 0.80 / 1.10. Duration and one-way/round-trip efficiencies remain unchanged. MACSE is a subset and is not summed twice. | K2: Slow and High multiply both charging power, discharging power and energy by 0.80 / 1.10. Duration and one-way/round-trip efficiencies remain unchanged. MACSE is a subset and is not summed twice. | L2: Slow and High multiply both charging power, discharging power and energy by 0.80 / 1.10. Duration and one-way/round-trip efficiencies remain unchanged. MACSE is a subset and is not summed twice. | M2: Slow and High multiply both charging power, discharging power and energy by 0.80 / 1.10. Duration and one-way/round-trip efficiencies remain unchanged. MACSE is a subset and is not summed twice. | N2: Slow and High multiply both charging power, discharging power and energy by 0.80 / 1.10. Duration and one-way/round-trip efficiencies remain unchanged. MACSE is a subset and is not summed twice. | O2: Slow and High multiply both charging power, discharging power and energy by 0.80 / 1.10. Duration and one-way/round-trip efficiencies remain unchanged. MACSE is a subset and is not summed twice. | P2: Slow and High multiply both charging power, discharging power and energy by 0.80 / 1.10. Duration and one-way/round-trip efficiencies remain unchanged. MACSE is a subset and is not summed twice.
A3: 2040 battery portfolio | B3: 2040 battery portfolio | C3: 2040 battery portfolio | D3: 2040 battery portfolio | E3: 2040 battery portfolio | F3: 2040 battery portfolio | G3: 2040 battery portfolio | H3: 2040 battery portfolio | I3: 2040 battery portfolio | J3: 2040 battery portfolio | K3: 2040 battery portfolio | L3: 2040 battery portfolio | M3: 2040 battery portfolio | N3: 2040 battery portfolio | O3: 2040 battery portfolio | P3: 2040 battery portfolio
A4: Zone | B4: Storage class | C4: Slow charge GW | D4: Slow discharge GW | E4: Slow energy GWh | F4: Base charge GW | G4: Base discharge GW | H4: Base energy GWh | I4: High charge GW | J4: High discharge GW | K4: High energy GWh | L4: Duration h | M4: Eta charge | N4: Eta discharge | O4: Round-trip | P4: Accounting / source
A5: NORD | B5: Small-scale 2h | C5: =F5*'02_SCENARIOS'!$I$5 -> 3.04 | D5: =G5*'02_SCENARIOS'!$I$5 -> 3.04 | E5: =H5*'02_SCENARIOS'!$I$5 -> 6.08 | F5: 3.8 | G5: 3.8 | H5: 7.6 | I5: =F5*'02_SCENARIOS'!$I$7 -> 4.18 | J5: =G5*'02_SCENARIOS'!$I$7 -> 4.18 | K5: =H5*'02_SCENARIOS'!$I$7 -> 8.36 | L5: 2 | M5: 0.9486833 | N5: 0.9486833 | O5: =M5*N5 -> 0.9 | P5: Primary input; v2.7/v2.6
A6: NORD | B6: Small-scale 4h | C6: =F6*'02_SCENARIOS'!$I$5 -> 0.76 | D6: =G6*'02_SCENARIOS'!$I$5 -> 0.76 | E6: =H6*'02_SCENARIOS'!$I$5 -> 3.04 | F6: 0.95 | G6: 0.95 | H6: 3.8 | I6: =F6*'02_SCENARIOS'!$I$7 -> 1.045 | J6: =G6*'02_SCENARIOS'!$I$7 -> 1.045 | K6: =H6*'02_SCENARIOS'!$I$7 -> 4.18 | L6: 4 | M6: 0.9486833 | N6: 0.9486833 | O6: =M6*N6 -> 0.9 | P6: Primary input; v2.7/v2.6
A7: NORD | B7: Capacity Market 4h | C7: =F7*'02_SCENARIOS'!$I$5 -> 0.62 | D7: =G7*'02_SCENARIOS'!$I$5 -> 0.62 | E7: =H7*'02_SCENARIOS'!$I$5 -> 2.48 | F7: 0.775 | G7: 0.775 | H7: 3.1 | I7: =F7*'02_SCENARIOS'!$I$7 -> 0.8525 | J7: =G7*'02_SCENARIOS'!$I$7 -> 0.8525 | K7: =H7*'02_SCENARIOS'!$I$7 -> 3.41 | L7: 4 | M7: 0.9486833 | N7: 0.9486833 | O7: =M7*N7 -> 0.9 | P7: Primary input; v2.7/v2.6
A8: NORD | B8: Utility-scale 8h | C8: =F8*'02_SCENARIOS'!$I$5 -> 0 | D8: =G8*'02_SCENARIOS'!$I$5 -> 0 | E8: =H8*'02_SCENARIOS'!$I$5 -> 0 | F8: 0 | G8: 0 | H8: 0 | I8: =F8*'02_SCENARIOS'!$I$7 -> 0 | J8: =G8*'02_SCENARIOS'!$I$7 -> 0 | K8: =H8*'02_SCENARIOS'!$I$7 -> 0 | L8: 8 | M8: 0.9486833 | N8: 0.9486833 | O8: =M8*N8 -> 0.9 | P8: Primary input; includes MACSE subset where allocated
A9: CNOR | B9: Small-scale 2h | C9: =F9*'02_SCENARIOS'!$I$5 -> 0.45333333 | D9: =G9*'02_SCENARIOS'!$I$5 -> 0.45333333 | E9: =H9*'02_SCENARIOS'!$I$5 -> 0.90666667 | F9: 0.56666667 | G9: 0.56666667 | H9: 1.1333333 | I9: =F9*'02_SCENARIOS'!$I$7 -> 0.62333333 | J9: =G9*'02_SCENARIOS'!$I$7 -> 0.62333333 | K9: =H9*'02_SCENARIOS'!$I$7 -> 1.2466667 | L9: 2 | M9: 0.9486833 | N9: 0.9486833 | O9: =M9*N9 -> 0.9 | P9: Primary input; v2.7/v2.6
A10: CNOR | B10: Small-scale 4h | C10: =F10*'02_SCENARIOS'!$I$5 -> 0.11333333 | D10: =G10*'02_SCENARIOS'!$I$5 -> 0.11333333 | E10: =H10*'02_SCENARIOS'!$I$5 -> 0.45333333 | F10: 0.14166667 | G10: 0.14166667 | H10: 0.56666667 | I10: =F10*'02_SCENARIOS'!$I$7 -> 0.15583333 | J10: =G10*'02_SCENARIOS'!$I$7 -> 0.15583333 | K10: =H10*'02_SCENARIOS'!$I$7 -> 0.62333333 | L10: 4 | M10: 0.9486833 | N10: 0.9486833 | O10: =M10*N10 -> 0.9 | P10: Primary input; v2.7/v2.6
A11: CNOR | B11: Capacity Market 4h | C11: =F11*'02_SCENARIOS'!$I$5 -> 0.02 | D11: =G11*'02_SCENARIOS'!$I$5 -> 0.02 | E11: =H11*'02_SCENARIOS'!$I$5 -> 0.08 | F11: 0.025 | G11: 0.025 | H11: 0.1 | I11: =F11*'02_SCENARIOS'!$I$7 -> 0.0275 | J11: =G11*'02_SCENARIOS'!$I$7 -> 0.0275 | K11: =H11*'02_SCENARIOS'!$I$7 -> 0.11 | L11: 4 | M11: 0.9486833 | N11: 0.9486833 | O11: =M11*N11 -> 0.9 | P11: Primary input; v2.7/v2.6
A12: CNOR | B12: Utility-scale 8h | C12: =F12*'02_SCENARIOS'!$I$5 -> 0.32 | D12: =G12*'02_SCENARIOS'!$I$5 -> 0.32 | E12: =H12*'02_SCENARIOS'!$I$5 -> 2.56 | F12: 0.4 | G12: 0.4 | H12: 3.2 | I12: =F12*'02_SCENARIOS'!$I$7 -> 0.44 | J12: =G12*'02_SCENARIOS'!$I$7 -> 0.44 | K12: =H12*'02_SCENARIOS'!$I$7 -> 3.52 | L12: 8 | M12: 0.9486833 | N12: 0.9486833 | O12: =M12*N12 -> 0.9 | P12: Primary input; includes MACSE subset where allocated
A13: CSUD | B13: Small-scale 2h | C13: =F13*'02_SCENARIOS'!$I$5 -> 0.77333333 | D13: =G13*'02_SCENARIOS'!$I$5 -> 0.77333333 | E13: =H13*'02_SCENARIOS'!$I$5 -> 1.5466667 | F13: 0.96666667 | G13: 0.96666667 | H13: 1.9333333 | I13: =F13*'02_SCENARIOS'!$I$7 -> 1.0633333 | J13: =G13*'02_SCENARIOS'!$I$7 -> 1.0633333 | K13: =H13*'02_SCENARIOS'!$I$7 -> 2.1266667 | L13: 2 | M13: 0.9486833 | N13: 0.9486833 | O13: =M13*N13 -> 0.9 | P13: Primary input; v2.7/v2.6
A14: CSUD | B14: Small-scale 4h | C14: =F14*'02_SCENARIOS'!$I$5 -> 0.19333333 | D14: =G14*'02_SCENARIOS'!$I$5 -> 0.19333333 | E14: =H14*'02_SCENARIOS'!$I$5 -> 0.77333333 | F14: 0.24166667 | G14: 0.24166667 | H14: 0.96666667 | I14: =F14*'02_SCENARIOS'!$I$7 -> 0.26583333 | J14: =G14*'02_SCENARIOS'!$I$7 -> 0.26583333 | K14: =H14*'02_SCENARIOS'!$I$7 -> 1.0633333 | L14: 4 | M14: 0.9486833 | N14: 0.9486833 | O14: =M14*N14 -> 0.9 | P14: Primary input; v2.7/v2.6
A15: CSUD | B15: Capacity Market 4h | C15: =F15*'02_SCENARIOS'!$I$5 -> 0.18 | D15: =G15*'02_SCENARIOS'!$I$5 -> 0.18 | E15: =H15*'02_SCENARIOS'!$I$5 -> 0.72 | F15: 0.225 | G15: 0.225 | H15: 0.9 | I15: =F15*'02_SCENARIOS'!$I$7 -> 0.2475 | J15: =G15*'02_SCENARIOS'!$I$7 -> 0.2475 | K15: =H15*'02_SCENARIOS'!$I$7 -> 0.99 | L15: 4 | M15: 0.9486833 | N15: 0.9486833 | O15: =M15*N15 -> 0.9 | P15: Primary input; v2.7/v2.6
A16: CSUD | B16: Utility-scale 8h | C16: =F16*'02_SCENARIOS'!$I$5 -> 2.23 | D16: =G16*'02_SCENARIOS'!$I$5 -> 2.23 | E16: =H16*'02_SCENARIOS'!$I$5 -> 17.84 | F16: 2.7875 | G16: 2.7875 | H16: 22.3 | I16: =F16*'02_SCENARIOS'!$I$7 -> 3.06625 | J16: =G16*'02_SCENARIOS'!$I$7 -> 3.06625 | K16: =H16*'02_SCENARIOS'!$I$7 -> 24.53 | L16: 8 | M16: 0.9486833 | N16: 0.9486833 | O16: =M16*N16 -> 0.9 | P16: Primary input; includes MACSE subset where allocated
... A32: SARD | B32: Utility-scale 8h | C32: =F32*'02_SCENARIOS'!$I$5 -> 2.03 | D32: =G32*'02_SCENARIOS'!$I$5 -> 2.03 | E32: =H32*'02_SCENARIOS'!$I$5 -> 16.24 | F32: 2.5375 | G32: 2.5375 | H32: 20.3 | I32: =F32*'02_SCENARIOS'!$I$7 -> 2.79125 | J32: =G32*'02_SCENARIOS'!$I$7 -> 2.79125 | K32: =H32*'02_SCENARIOS'!$I$7 -> 22.33 | L32: 8 | M32: 0.9486833 | N32: 0.9486833 | O32: =M32*N32 -> 0.9 | P32: Primary input; includes MACSE subset where allocated
A33: NATIONAL | B33: TOTAL 2040 | C33: =SUM(C5:C32) -> 21.813333 | D33: =SUM(D5:D32) -> 21.813333 | E33: =SUM(E5:E32) -> 133.12 | F33: =SUM(F5:F32) -> 27.266667 | G33: =SUM(G5:G32) -> 27.266667 | H33: =SUM(H5:H32) -> 166.4 | I33: =SUM(I5:I32) -> 29.993333 | J33: =SUM(J5:J32) -> 29.993333 | K33: =SUM(K5:K32) -> 183.04 | M33: 0.9486833 | N33: 0.9486833 | O33: =M33*N33 -> 0.9 | P33: Formula; MACSE not added separately
A36: 2050 battery portfolio | B36: 2050 battery portfolio | C36: 2050 battery portfolio | D36: 2050 battery portfolio | E36: 2050 battery portfolio | F36: 2050 battery portfolio | G36: 2050 battery portfolio | H36: 2050 battery portfolio | I36: 2050 battery portfolio | J36: 2050 battery portfolio | K36: 2050 battery portfolio | L36: 2050 battery portfolio | M36: 2050 battery portfolio | N36: 2050 battery portfolio | O36: 2050 battery portfolio | P36: 2050 battery portfolio
A37: Zone | B37: Storage class | C37: Slow charge GW | D37: Slow discharge GW | E37: Slow energy GWh | F37: Base charge GW | G37: Base discharge GW | H37: Base energy GWh | I37: High charge GW | J37: High discharge GW | K37: High energy GWh | L37: Duration h | M37: Eta charge | N37: Eta discharge | O37: Round-trip | P37: Accounting / source
